<?xml version="1.0"?>
<robot name="screw_with_nut">
  <!-- Base: Wide cylinder with hole -->
  <link name="base">
    <visual>
      <origin xyz="0 0 0" />
      <geometry>
        <cylinder radius="0.1" length="0.01" />
      </geometry>
      <material name="base_material">
        <color rgba="0.6 0.6 0.6 1" />
      </material>
    </visual>
    <collision>
      <origin xyz="0 0 0" />
      <geometry>
        <cylinder radius="0.1" length="0.01" />
      </geometry>
    </collision>
    <inertial>
      <mass value="10.0" />
      <origin xyz="0 0 0" />
      <inertia ixx="0.02508" ixy="0.0" ixz="0.0" iyy="0.02508" iyz="0.0" izz="0.05" />
    </inertial>
  </link>

  <!-- Bolt rigidly attached to base -->
  <link name="bolt">
    <visual>
      <origin xyz="0 0 0.05" />
      <geometry>
        <cylinder radius="0.0125" length="0.1" />
      </geometry>
      <material name="bolt_material">
        <color rgba="0.6 0.6 0.6 1" />
      </material>
    </visual>
    <collision>
      <origin xyz="0 0 0.05" />
      <geometry>
        <cylinder radius="0.0125" length="0.1" />
      </geometry>
    </collision>
    <inertial>
      <mass value="0.05" />
      <origin xyz="0 0 0.05" />
      <inertia ixx="0.0000420" ixy="0.0" ixz="0.0" iyy="0.0000420" iyz="0.0" izz="0.000000625" />
    </inertial>
  </link>

  <!-- Nut: triangular prism that will rotate around the screw -->
  <link name="nut">
    <visual>
      <origin xyz="0 0 -0.08"/>
      <geometry>
        <mesh filename="../meshes/tri.stl" scale="1.0 1.0 6.5"/>
      </geometry>
      <material name="nut_material">
        <color rgba="0.8 0.4 0.2 1"/>
      </material>
    </visual>
    <collision>
      <origin xyz="0 0 -0.08"/>
      <geometry>
        <mesh filename="../meshes/tri.stl" scale="1.0 1.0 6.5"/>
      </geometry>
    </collision>
    <inertial>
      <mass value="0.05"/>
      <origin xyz="0 0 0"/>
      <inertia ixx="0.000005157" iyy="0.000005157" izz="0.000008438" ixy="0" ixz="0" iyz="0"/>
    </inertial>
    <!-- Red stripe on nut -->
    <visual>
      <origin xyz="0 0 0" rpy="0 0 0"/>
      <geometry>
        <!-- thin box wrapping around the cylinder -->
        <box size="0.002 0.05 0.03"/>
      </geometry>
      <material name="stripe_red">
        <color rgba="1 0 0 1"/>
      </material>
    </visual>

    <!-- Blue stripe on nut -->
    <visual>
      <origin xyz="0 0 0" rpy="0 0 1.5708"/>
      <geometry>
        <box size="0.002 0.05 0.03"/>
      </geometry>
      <material name="stripe_blue">
        <color rgba="0 0 1 1"/>
      </material>
    </visual>
  </link>

  <!-- Fixed joint -->
  <joint name="base_screw_fixed" type="fixed">
    <parent link="base" />
    <child  link="bolt" />
    <origin xyz="0 0 0" rpy="0 0 0" />
  </joint>

  <!-- Revolute joint -->
  <joint name="nut_joint" type="revolute">
    <parent link="bolt" />
    <child  link="nut" />
    <origin xyz="0 0 0.1" rpy="0 0 0"/>
    <axis  xyz="0 0 -1" />
    <dynamics friction="0.2"/>
    <limit lower="0.0" upper="628.3185" effort="2.0" velocity="6.2832" /> <!-- 100 rotations -->
  </joint>
</robot>