<?xml version="1.0"?>
<robot name="screwdriver">

  <!-- ========== BASE (wide cylinder) ========== -->
  <link name="base">
    <visual>
      <origin xyz="0 0 0" />
      <geometry>
        <cylinder radius="0.1" length="0.01" />
      </geometry>
      <material name="base_material">
        <color rgba="0.6 0.6 0.6 1" />
      </material>
    </visual>
    <collision>
      <origin xyz="0 0 0" />
      <geometry>
        <cylinder radius="0.1" length="0.01" />
      </geometry>
    </collision>
    <inertial>
      <mass value="10.0" />
      <origin xyz="0 0 0" />
      <inertia ixx="0.02508" ixy="0.0" ixz="0.0" iyy="0.02508" iyz="0.0" izz="0.05" />
    </inertial>
  </link>

  <!-- ========== HANDLE (upper, orange) ========== -->
  <link name="handle">
    <visual>
      <origin xyz="0 0 0.01" />
      <geometry>
        <mesh filename="../meshes/screw_upper_12.stl" />
      </geometry>
      <material name="handle_orange">
        <color rgba="0.8 0.4 0.2 1"/>
      </material>
    </visual>
    <collision>
      <origin xyz="0 0 0.01" />
      <geometry>
        <mesh filename="../meshes/screw_upper_12.stl" />
      </geometry>
    </collision>
    <inertial>
      <origin xyz="0 0 0.01" />
      <mass value="0.05595962"/>
      <inertia ixx="0.0000442722195" ixy="0" ixz="0"
               iyy="0.0000442722195" iyz="0"
               izz="0.00000437184525"/>
    </inertial>
    <!-- Red stripe on nut -->
    <visual>
      <origin xyz="0 0 0.06" rpy="0 0 0"/>
      <geometry>
        <!-- thin box wrapping around the cylinder -->
        <box size="0.002 0.03 0.1"/>
      </geometry>
      <material name="stripe_red">
        <color rgba="1 0 0 1"/>
      </material>
    </visual>

    <!-- Blue stripe on nut -->
    <visual>
      <origin xyz="0 0 0.06" rpy="0 0 1.5708"/>
      <geometry>
        <box size="0.002 0.03 0.1"/>
      </geometry>
      <material name="stripe_blue">
        <color rgba="0 0 1 1"/>
      </material>
    </visual>
  </link>

  <!-- ========== SHAFT (lower, gray) ========== -->
  <link name="shaft">
    <visual>
      <origin xyz="0 0 0.01" />
      <geometry>
        <cylinder radius="0.00625" length="0.02" />
      </geometry>
      <material name="shaft_gray">
        <color rgba="0.6 0.6 0.6 1"/>
      </material>
    </visual>
    <collision>
      <origin xyz="0 0 0.01" />
      <geometry>
        <cylinder radius="0.00625" length="0.02" />
      </geometry>
    </collision>
    <inertial>
      <origin xyz="0 0 0.05" />
      <mass value="0.01233075"/>
      <inertia ixx="0.00000659566742" ixy="0" ixz="0"
               iyy="0.00000659566742" iyz="0"
               izz="0.0000000385335974"/>
    </inertial>
  </link>

  <!-- Base–shaft connection (fixed) -->
  <joint name="base_to_shaft" type="fixed">
    <parent link="base" />
    <child  link="shaft" />
    <origin xyz="0 0 0" rpy="0 0 0" />
  </joint>

  <!-- Handle–shaft connection (revolute joint for training)-->
  <joint name="handle_to_shaft" type="revolute">
    <parent link="shaft"/>
    <child  link="handle"/>
    <origin xyz="0 0 0.01" rpy="0 0 0"/>
    <axis  xyz="0 0 -1" />
    <dynamics friction="0.2"/>
    <limit lower="0.0" upper="628.3185" effort="2.0" velocity="6.2832" /> <!-- 100 rotations -->
  </joint>
</robot>